Workbook

Sheet allotment
A1: Sno | B1: Course Name | C1: Year | D1: Students | E1: Hostel | F1: Domain | H1: Finding out necessary
A2: 1 | B2: M.Sc (Bio-informatics) | C2: Final | D2: 5 | E2: Maple | F2: Science and Technology | H2: details of a particular entry
A3: 2 | B3: M.Sc (AMBT) | C3: Final | D3: 15 | E3: Maple | F3: Science and Technology | H3: on row 156
A4: 3 | B4: M.Sc (Biotechnology) | C4: Final | D4: 51 | E4: Maple | F4: Science and Technology
A5: 4 | B5: M.Sc (Botany) | C5: Final | D5: 8 | E5: Maple | F5: Science and Technology
A6: 5 | B6: M.Sc (Zoology) | C6: Final | D6: 25 | E6: Maple | F6: Science and Technology
A7: 6 | B7: M.Sc (Chemistry) | C7: Final | D7: 20 | E7: Maple | F7: Science and Technology
A8: 7 | B8: M.Sc (Microbiology) | C8: Final | D8: 6 | E8: Maple | F8: Science and Technology
A9: 8 | B9: MCA | C9: 2 | D9: 110 | E9: Maple | F9: Science and Technology
A10: 9 | B10: M.Sc (Computer Science) | C10: Final | D10: 3 | E10: Maple | F10: Science and Technology
A11: 10 | B11: M.Sc (Physics) | C11: Final | D11: 20 | E11: Maple | F11: Science and Technology
A12: 11 | B12: M.Sc (Mathematics) | C12: Final | D12: 25 | E12: Maple | F12: Science and Technology
A13: 12 | B13: M.Sc (Data Science) | C13: Final | D13: 8 | E13: Maple | F13: Science and Technology
A14: 13 | B14: M.Pharma | C14: Final | D14: 25 | E14: Maple | F14: Pharmacy
A15: 14 | B15: M.Tech | C15: Previous | D15: 50 | E15: Maple | F15: Science and Technology
A16: 15 | B16: LL.M | C16: Previous | D16: 15 | E16: Maple | F16: Law
A17: 16 | B17: B.Tech (AI) | C17: 2 | D17: 130 | E17: Oak | F17: Science and Technology
A18: 17 | B18: B.Tech (CE) | C18: 2 | D18: 28 | E18: Oak | F18: Science and Technology
A19: 18 | B19: B.Tech (IT) | C19: 2 | D19: 124 | E19: Oak | F19: Science and Technology
A20: 19 | B20: B.Com | C20: 2 | D20: 140 | E20: Cedar | F20: Commerce
A21: 20 | B21: M.Ed | C21: 1 | D21: 10 | E21: Cedar | F21: Education
A22: 21 | B22: B.Tech | C22: 1 | D22: 276 | E22: Pine | F22: Science and Technology
A23: 22 | B23: B.Sc (Geology) | C23: 2 | D23: 14 | E23: Willow | F23: Science and Technology
A24: 23 | B24: B.Sc (Maths) | C24: 2 | D24: 81 | E24: Willow | F24: Science and Technology
A25: 24 | B25: B.Sc (Home Science) | C25: 2 | D25: 11 | E25: Willow | F25: Science and Technology
A26: 25 | B26: B.Sc (Home Science FN) | C26: 2 | D26: 18 | E26: Willow | F26: Science and Technology
A27: 26 | B27: B.A (JMC) | C27: 3 | D27: 47 | E27: Willow | F27: Journalism
A28: 27 | B28: B.Sc/B.A (B.Ed) | C28: 2 | D28: 92 | E28: Willow | F28: Education
A29: 28 | B29: M.Sc (Geology) | C29: Final | D29: 2 | E29: Willow | F29: Science and Technology
A30: 29 | B30: M.Ed | C30: 2 | D30: 8 | E30: Willow | F30: Education
A31: 30 | B31: B.Tech(CS) | C31: 3 | D31: 276 | E31: Birch | F31: Science and Technology
A32: 31 | B32: LL.B (Integrated) | C32: 2 | D32: 215 | E32: Elm | F32: Law
A33: 32 | B33: B.Pharma | C33: 2 | D33: 55 | E33: Elm | F33: Pharmacy
A34: 33 | B34: B.A | C34: 1 | D34: 450 | E34: Almond | F34: Arts
A35: 34 | B35: M.A | C35: Final | D35: 127 | E35: Redwood | F35: Arts
A36: 35 | B36: M.A (Textile Designing) | C36: Final | D36: 2 | E36: Redwood | F36: Design
A37: 36 | B37: M.Social Work | C37: Final | D37: 6 | E37: Redwood | F37: Social Work
A38: 37 | B38: M.Des | C38: 1 | D38: 10 | E38: Redwood | F38: Design
A39: 38 | B39: M.A (JMC) | C39: Previous | D39: 10 | E39: Redwood | F39: Journalism
A40: 39 | B40: M.A (JMC) | C40: Final | D40: 4 | E40: Redwood | F40: Journalism
...

Sheet hostels
A1: s_no | B1: hostel_name | C1: capacity | D1: students_num (sumif) | E1: hostel_id | F1: capacity status (if function)
A2: 1 | B2: Maple | C2: 392 | D2: =SUMIF(allotment!E:E, "Maple", allotment!D:D) -> 386 | E2: H-001 | F2: =IF(D2>C2, "overcapacity", IF(D2=C2, "on capacity", "undercapacity")) -> undercapacity
A3: 2 | B3: Oak | C3: 270 | D3: =SUMIF(allotment!E:E, "Oak", allotment!D:D) -> 282 | E3: H-002 | F3: =IF(D3>C3, "overcapacity", IF(D3=C3, "on capacity", "undercapacity")) -> overcapacity
A4: 3 | B4: Cedar | C4: 154 | D4: =SUMIF(allotment!E:E, "Cedar", allotment!D:D) -> 150 | E4: H-003 | F4: =IF(D4>C4, "overcapacity", IF(D4=C4, "on capacity", "undercapacity")) -> undercapacity
A5: 4 | B5: Pine | C5: 270 | D5: =SUMIF(allotment!E:E, "Pine", allotment!D:D) -> 276 | E5: H-004 | F5: =IF(D5>C5, "overcapacity", IF(D5=C5, "on capacity", "undercapacity")) -> overcapacity
A6: 5 | B6: Willow | C6: 272 | D6: =SUMIF(allotment!E:E, "Willow", allotment!D:D) -> 273 | E6: H-005 | F6: =IF(D6>C6, "overcapacity", IF(D6=C6, "on capacity", "undercapacity")) -> overcapacity
A7: 6 | B7: Birch | C7: 270 | D7: =SUMIF(allotment!E:E, "Birch", allotment!D:D) -> 276 | E7: H-006 | F7: =IF(D7>C7, "overcapacity", IF(D7=C7, "on capacity", "undercapacity")) -> overcapacity
A8: 7 | B8: Elm | C8: 272 | D8: =SUMIF(allotment!E:E, "Elm", allotment!D:D) -> 270 | E8: H-007 | F8: =IF(D8>C8, "overcapacity", IF(D8=C8, "on capacity", "undercapacity")) -> undercapacity
A9: 8 | B9: Almond | C9: 453 | D9: =SUMIF(allotment!E:E, "Almond", allotment!D:D) -> 450 | E9: H-008 | F9: =IF(D9>C9, "overcapacity", IF(D9=C9, "on capacity", "undercapacity")) -> undercapacity
A10: 9 | B10: Redwood | C10: 159 | D10: =SUMIF(allotment!E:E, "Redwood", allotment!D:D) -> 159 | E10: H-009 | F10: =IF(D10>C10, "overcapacity", IF(D10=C10, "on capacity", "undercapacity")) -> on capacity
A11: 10 | B11: Cypress | C11: 332 | D11: =SUMIF(allotment!E:E, "Cypress", allotment!D:D) -> 332 | E11: H-010 | F11: =IF(D11>C11, "overcapacity", IF(D11=C11, "on capacity", "undercapacity")) -> on capacity
A12: 11 | B12: Spruce | C12: 414 | D12: =SUMIF(allotment!E:E, "Spruce", allotment!D:D) -> 414 | E12: H-011 | F12: =IF(D12>C12, "overcapacity", IF(D12=C12, "on capacity", "undercapacity")) -> on capacity
A13: 12 | B13: Alder | C13: 273 | D13: =SUMIF(allotment!E:E, "Alder", allotment!D:D) -> 276 | E13: H-012 | F13: =IF(D13>C13, "overcapacity", IF(D13=C13, "on capacity", "undercapacity")) -> overcapacity
A14: 13 | B14: Poplar | C14: 485 | D14: =SUMIF(allotment!E:E, "Poplar", allotment!D:D) -> 480 | E14: H-013 | F14: =IF(D14>C14, "overcapacity", IF(D14=C14, "on capacity", "undercapacity")) -> undercapacity
A15: 14 | B15: Walnut | C15: 492 | D15: =SUMIF(allotment!E:E, "Walnut", allotment!D:D) -> 491 | E15: H-014 | F15: =IF(D15>C15, "overcapacity", IF(D15=C15, "on capacity", "undercapacity")) -> undercapacity
A16: 15 | B16: Chestnut | C16: 330 | D16: =SUMIF(allotment!E:E, "Chestnut", allotment!D:D) -> 326 | E16: H-015 | F16: =IF(D16>C16, "overcapacity", IF(D16=C16, "on capacity", "undercapacity")) -> undercapacity
A17: 16 | B17: Sycamore | C17: 542 | D17: =SUMIF(allotment!E:E, "Sycamore", allotment!D:D) -> 540 | E17: H-016 | F17: =IF(D17>C17, "overcapacity", IF(D17=C17, "on capacity", "undercapacity")) -> undercapacity
A18: 17 | B18: Magnolia | C18: 270 | D18: =SUMIF(allotment!E:E, "Magnolia", allotment!D:D) -> 273 | E18: H-017 | F18: =IF(D18>C18, "overcapacity", IF(D18=C18, "on capacity", "undercapacity")) -> overcapacity
A19: 18 | B19: Juniper | C19: 294 | D19: =SUMIF(allotment!E:E, "Juniper", allotment!D:D) -> 292 | E19: H-018 | F19: =IF(D19>C19, "overcapacity", IF(D19=C19, "on capacity", "undercapacity")) -> undercapacity
A20: 19 | B20: Sequoia | C20: 364 | D20: =SUMIF(allotment!E:E, "Sequoia", allotment!D:D) -> 363 | E20: H-019 | F20: =IF(D20>C20, "overcapacity", IF(D20=C20, "on capacity", "undercapacity")) -> undercapacity
A21: 20 | B21: Bamboo | C21: 206 | D21: =SUMIF(allotment!E:E, "Bamboo", allotment!D:D) -> 206 | E21: H-020 | F21: =IF(D21>C21, "overcapacity", IF(D21=C21, "on capacity", "undercapacity")) -> on capacity
A22: 21 | B22: Teak | C22: 256 | D22: =SUMIF(allotment!E:E, "Teak", allotment!D:D) -> 259 | E22: H-021 | F22: =IF(D22>C22, "overcapacity", IF(D22=C22, "on capacity", "undercapacity")) -> overcapacity
A23: 22 | B23: Ebony | C23: 270 | D23: =SUMIF(allotment!E:E, "Ebony", allotment!D:D) -> 276 | E23: H-022 | F23: =IF(D23>C23, "overcapacity", IF(D23=C23, "on capacity", "undercapacity")) -> overcapacity
A24: 23 | B24: Rosewood | C24: 270 | D24: =SUMIF(allotment!E:E, "Rosewood", allotment!D:D) -> 270 | E24: H-023 | F24: =IF(D24>C24, "overcapacity", IF(D24=C24, "on capacity", "undercapacity")) -> on capacity
A25: 24 | B25: Sandalwood | C25: 270 | D25: =SUMIF(allotment!E:E, "Sandalwood", allotment!D:D) -> 276 | E25: H-024 | F25: =IF(D25>C25, "overcapacity", IF(D25=C25, "on capacity", "undercapacity")) -> overcapacity
A26: 25 | B26: Acacia | C26: 396 | D26: =SUMIF(allotment!E:E, "Acacia", allotment!D:D) -> 407 | E26: H-025 | F26: =IF(D26>C26, "overcapacity", IF(D26=C26, "on capacity", "undercapacity")) -> overcapacity
A27: 26 | B27: Baobab | C27: 545 | D27: =SUMIF(allotment!E:E, "Baobab", allotment!D:D) -> 545 | E27: H-026 | F27: =IF(D27>C27, "overcapacity", IF(D27=C27, "on capacity", "undercapacity")) -> on capacity
A28: 27 | B28: Palm | C28: 280 | D28: =SUMIF(allotment!E:E, "Palm", allotment!D:D) -> 280 | E28: H-027 | F28: =IF(D28>C28, "overcapacity", IF(D28=C28, "on capacity", "undercapacity")) -> on capacity
A29: 28 | B29: Fir | C29: 317 | D29: =SUMIF(allotment!E:E, "Fir", allotment!D:D) -> 321 | E29: H-028 | F29: =IF(D29>C29, "overcapacity", IF(D29=C29, "on capacity", "undercapacity")) -> overcapacity
A30: 29 | B30: Larch | C30: 294 | D30: =SUMIF(allotment!E:E, "Larch", allotment!D:D) -> 292 | E30: H-029 | F30: =IF(D30>C30, "overcapacity", IF(D30=C30, "on capacity", "undercapacity")) -> undercapacity
A31: 30 | B31: Hemlock | C31: 518 | D31: =SUMIF(allotment!E:E, "Hemlock", allotment!D:D) -> 519 | E31: H-030 | F31: =IF(D31>C31, "overcapacity", IF(D31=C31, "on capacity", "undercapacity")) -> overcapacity
A32: 31 | B32: Tamarind | C32: 292 | D32: =SUMIF(allotment!E:E, "Tamarind", allotment!D:D) -> 295 | E32: H-031 | F32: =IF(D32>C32, "overcapacity", IF(D32=C32, "on capacity", "undercapacity")) -> overcapacity
A33: 32 | B33: Neem | C33: 247 | D33: =SUMIF(allotment!E:E, "Neem", allotment!D:D) -> 245 | E33: H-032 | F33: =IF(D33>C33, "overcapacity", IF(D33=C33, "on capacity", "undercapacity")) -> undercapacity
A34: 33 | B34: Peepal | C34: 294 | D34: =SUMIF(allotment!E:E, "Peepal", allotment!D:D) -> 280 | E34: H-033 | F34: =IF(D34>C34, "overcapacity", IF(D34=C34, "on capacity", "undercapacity")) -> undercapacity
A35: 34 | B35: Banyan | C35: 586 | D35: =SUMIF(allotment!E:E, "Banyan", allotment!D:D) -> 588 | E35: H-034 | F35: =IF(D35>C35, "overcapacity", IF(D35=C35, "on capacity", "undercapacity")) -> overcapacity
A36: 35 | B36: Gulmohar | C36: 270 | D36: =SUMIF(allotment!E:E, "Gulmohar", allotment!D:D) -> 277 | E36: H-035 | F36: =IF(D36>C36, "overcapacity", IF(D36=C36, "on capacity", "undercapacity")) -> overcapacity
A37: 36 | B37: Amaltas | C37: 294 | D37: =SUMIF(allotment!E:E, "Amaltas", allotment!D:D) -> 290 | E37: H-036 | F37: =IF(D37>C37, "overcapacity", IF(D37=C37, "on capacity", "undercapacity")) -> undercapacity
A38: 37 | B38: Kadamba | C38: 402 | D38: =SUMIF(allotment!E:E, "Kadamba", allotment!D:D) -> 400 | E38: H-037 | F38: =IF(D38>C38, "overcapacity", IF(D38=C38, "on capacity", "undercapacity")) -> undercapacity
A39: 38 | B39: Arjuna | C39: 411 | D39: =SUMIF(allotment!E:E, "Arjuna", allotment!D:D) -> 411 | E39: H-038 | F39: =IF(D39>C39, "overcapacity", IF(D39=C39, "on capacity", "undercapacity")) -> on capacity
A40: 39 | B40: Sal | C40: 272 | D40: =SUMIF(allotment!E:E, "Sal", allotment!D:D) -> 278 | E40: H-039 | F40: =IF(D40>C40, "overcapacity", IF(D40=C40, "on capacity", "undercapacity")) -> overcapacity
...

Sheet pivot tables
A1: Table Showing number of | D1: Table showing overall hostel capacity
A2: Students in each hostel | D2: status
A4: Hostel Name | B4: Sum of Students | D4: Capacity Status | E4: Count of hostel_name
A5: Acacia | B5: 407 | D5: on capacity | E5: 8
A6: Alder | B6: 276 | D6: overcapacity | E6: 16
A7: Almond | B7: 450 | D7: undercapacity | E7: 15
A8: Amaltas | B8: 290 | D8: Grand Total | E8: 39
A9: Arjuna | B9: 411
A10: Bamboo | B10: 206
A11: Banyan | B11: 588
A12: Baobab | B12: 545 | D12: Table showing the number of students in
A13: Birch | B13: 276 | D13: each domain, further segregated by courses
A14: Cedar | B14: 150
A15: Chestnut | B15: 326 | D15: Domain | E15: Sum of Students
A16: Cypress | B16: 332 | D16: Architecture | E16: 62
A17: Ebony | B17: 276 | D17: Arts | E17: 1531
A18: Elm | B18: 270 | D18: Aviation | E18: 64
A19: Fir | B19: 321 | D19: Commerce | E19: 1890
A20: Gulmohar | B20: 277 | D20: Design | E20: 390
A21: Hemlock | B21: 519 | D21: Education | E21: 513
A22: Juniper | B22: 292 | D22: Journalism | E22: 153
A23: Kadamba | B23: 400 | D23: Law | E23: 1120
A24: Larch | B24: 292 | D24: Nursing | E24: 194
A25: Magnolia | B25: 273 | D25: Pharmacy | E25: 287
A26: Maple | B26: 386 | D26: Project | E26: 81
A27: Neem | B27: 245 | D27: Research | E27: 486
... A30: Peepal | B30: 280 | D30: Grand Total | E30: 13024
A31: Pine | B31: 276
A32: Poplar | B32: 480
A33: Redwood | B33: 159
A34: Rosewood | B34: 270
A35: Sal | B35: 278
A36: Sandalwood | B36: 276
A37: Sequoia | B37: 363
A38: Spruce | B38: 414
A39: Sycamore | B39: 540
A40: Tamarind | B40: 295
A41: Teak | B41: 259
A42: Walnut | B42: 491
... A44: Grand Total | B44: 13024
